Workbook

Sheet microcode
C1: LD.MAR (1) | D1: LD.MDR (1) | E1: LD.IR (1) | F1: LD.REG (1) | G1: LD.CC (1) | H1: LD.PC (1) | I1: GatePC (1) | J1: GateMDR (1) | K1: GateALU (1) | L1: GateMARMUX (1) | M1: PCMUX (2) | O1: DRMUX (1) | P1: SR1MUX (1) | Q1: ADDR1MUX (1) | R1: ADDR2MUX (2) | T1: MARMUX (1) | U1: ALUK (2) | W1: MEM.EN (1) | X1: R.W (1) | Y1: NEXT (6 bits)
AH2: OUTPUT
A3: INC
A4: INC1 | O4: 0 | P4: 0 | Y4: 0 | Z4: 0 | AA4: 1 | AB4: 0 | AC4: 0 | AD4: 0 | AH4: =_xlfn.CONCAT(BIN2HEX(_xlfn.CONCAT(C4:F4), 1), BIN2HEX(_xlfn.CONCAT(G4:N4), 2), BIN2HEX(_xlfn.CONCAT(O4:V4), 2), BIN2HEX(_xlfn.CONCAT(W4:AD4), 2) ) -> 0000008
A5: LDPC
A7: LDPC1 | O7: 0 | P7: 0 | Y7: 0 | Z7: 1 | AA7: 0 | AB7: 1 | AC7: 1 | AD7: 1 | AH7: =_xlfn.CONCAT(BIN2HEX(_xlfn.CONCAT(C7:F7), 1), BIN2HEX(_xlfn.CONCAT(G7:N7), 2), BIN2HEX(_xlfn.CONCAT(O7:V7), 2), BIN2HEX(_xlfn.CONCAT(W7:AD7), 2) ) -> 0000017
A8: LDPC2 | O8: 0 | P8: 0 | Y8: 1 | Z8: 0 | AA8: 0 | AB8: 1 | AC8: 1 | AD8: 1 | AH8: =_xlfn.CONCAT(BIN2HEX(_xlfn.CONCAT(C8:F8), 1), BIN2HEX(_xlfn.CONCAT(G8:N8), 2), BIN2HEX(_xlfn.CONCAT(O8:V8), 2), BIN2HEX(_xlfn.CONCAT(W8:AD8), 2) ) -> 0000027
A9: LDPC3 | O9: 0 | P9: 0 | Y9: 0 | Z9: 0 | AA9: 1 | AB9: 0 | AC9: 0 | AD9: 0 | AH9: =_xlfn.CONCAT(BIN2HEX(_xlfn.CONCAT(C9:F9), 1), BIN2HEX(_xlfn.CONCAT(G9:N9), 2), BIN2HEX(_xlfn.CONCAT(O9:V9), 2), BIN2HEX(_xlfn.CONCAT(W9:AD9), 2) ) -> 0000008
A10: LJSR
A12: LJSR1 | O12: 0 | P12: 0 | Y12: 0 | Z12: 0 | AA12: 1 | AB12: 0 | AC12: 0 | AD12: 0 | AH12: =_xlfn.CONCAT(BIN2HEX(_xlfn.CONCAT(C12:F12), 1), BIN2HEX(_xlfn.CONCAT(G12:N12), 2), BIN2HEX(_xlfn.CONCAT(O12:V12), 2), BIN2HEX(_xlfn.CONCAT(W12:AD12), 2) ) -> 0000008
A13: MULT8
A15: MULT81 | O15: 0 | P15: 1 | Y15: 0 | Z15: 1 | AA15: 0 | AB15: 1 | AC15: 1 | AD15: 0 | AH15: =_xlfn.CONCAT(BIN2HEX(_xlfn.CONCAT(C15:F15), 1), BIN2HEX(_xlfn.CONCAT(G15:N15), 2), BIN2HEX(_xlfn.CONCAT(O15:V15), 2), BIN2HEX(_xlfn.CONCAT(W15:AD15), 2) ) -> 0000116
A16: MULT82 | O16: 0 | P16: 1 | Y16: 1 | Z16: 0 | AA16: 0 | AB16: 1 | AC16: 1 | AD16: 0 | AH16: =_xlfn.CONCAT(BIN2HEX(_xlfn.CONCAT(C16:F16), 1), BIN2HEX(_xlfn.CONCAT(G16:N16), 2), BIN2HEX(_xlfn.CONCAT(O16:V16), 2), BIN2HEX(_xlfn.CONCAT(W16:AD16), 2) ) -> 0000126
A17: MULT83 | O17: 0 | P17: 1 | Y17: 0 | Z17: 0 | AA17: 1 | AB17: 0 | AC17: 0 | AD17: 0 | AH17: =_xlfn.CONCAT(BIN2HEX(_xlfn.CONCAT(C17:F17), 1), BIN2HEX(_xlfn.CONCAT(G17:N17), 2), BIN2HEX(_xlfn.CONCAT(O17:V17), 2), BIN2HEX(_xlfn.CONCAT(W17:AD17), 2) ) -> 0000108
A18: LDAR
A19: LDAR1 | O19: 0 | P19: 1 | Y19: 0 | Z19: 1 | AA19: 0 | AB19: 0 | AC19: 1 | AD19: 1 | AH19: =_xlfn.CONCAT(BIN2HEX(_xlfn.CONCAT(C19:F19), 1), BIN2HEX(_xlfn.CONCAT(G19:N19), 2), BIN2HEX(_xlfn.CONCAT(O19:V19), 2), BIN2HEX(_xlfn.CONCAT(W19:AD19), 2) ) -> 0000113
A20: LDAR2 | O20: 0 | P20: 0 | Y20: 1 | Z20: 0 | AA20: 0 | AB20: 0 | AC20: 1 | AD20: 1 | AH20: =_xlfn.CONCAT(BIN2HEX(_xlfn.CONCAT(C20:F20), 1), BIN2HEX(_xlfn.CONCAT(G20:N20), 2), BIN2HEX(_xlfn.CONCAT(O20:V20), 2), BIN2HEX(_xlfn.CONCAT(W20:AD20), 2) ) -> 0000023
A21: LDAR3 | O21: 0 | P21: 0 | Y21: 0 | Z21: 0 | AA21: 1 | AB21: 0 | AC21: 0 | AD21: 0 | AH21: =_xlfn.CONCAT(BIN2HEX(_xlfn.CONCAT(C21:F21), 1), BIN2HEX(_xlfn.CONCAT(G21:N21), 2), BIN2HEX(_xlfn.CONCAT(O21:V21), 2), BIN2HEX(_xlfn.CONCAT(W21:AD21), 2) ) -> 0000008
A22: STPCI
A23: STPCI1 | O23: 0 | P23: 0 | Y23: 0 | Z23: 1 | AA23: 1 | AB23: 0 | AC23: 1 | AD23: 0 | AH23: =_xlfn.CONCAT(BIN2HEX(_xlfn.CONCAT(C23:F23), 1), BIN2HEX(_xlfn.CONCAT(G23:N23), 2), BIN2HEX(_xlfn.CONCAT(O23:V23), 2), BIN2HEX(_xlfn.CONCAT(W23:AD23), 2) ) -> 000001A
A24: STPCI2 | O24: 0 | P24: 0 | Y24: 1 | Z24: 0 | AA24: 1 | AB24: 0 | AC24: 1 | AD24: 0 | AH24: =_xlfn.CONCAT(BIN2HEX(_xlfn.CONCAT(C24:F24), 1), BIN2HEX(_xlfn.CONCAT(G24:N24), 2), BIN2HEX(_xlfn.CONCAT(O24:V24), 2), BIN2HEX(_xlfn.CONCAT(W24:AD24), 2) ) -> 000002A
A25: STPCI3 | O25: 0 | P25: 0 | Y25: 1 | Z25: 1 | AA25: 1 | AB25: 0 | AC25: 1 | AD25: 0 | AH25: =_xlfn.CONCAT(BIN2HEX(_xlfn.CONCAT(C25:F25), 1), BIN2HEX(_xlfn.CONCAT(G25:N25), 2), BIN2HEX(_xlfn.CONCAT(O25:V25), 2), BIN2HEX(_xlfn.CONCAT(W25:AD25), 2) ) -> 000003A
A26: STPCI4 | O26: 0 | P26: 0 | Y26: 0 | Z26: 1 | AA26: 1 | AB26: 1 | AC26: 0 | AD26: 1 | AH26: =_xlfn.CONCAT(BIN2HEX(_xlfn.CONCAT(C26:F26), 1), BIN2HEX(_xlfn.CONCAT(G26:N26), 2), BIN2HEX(_xlfn.CONCAT(O26:V26), 2), BIN2HEX(_xlfn.CONCAT(W26:AD26), 2) ) -> 000001D
A27: STPCI5 | O27: 0 | P27: 0 | Y27: 0 | Z27: 0 | AA27: 1 | AB27: 0 | AC27: 0 | AD27: 0 | AH27: =_xlfn.CONCAT(BIN2HEX(_xlfn.CONCAT(C27:F27), 1), BIN2HEX(_xlfn.CONCAT(G27:N27), 2), BIN2HEX(_xlfn.CONCAT(O27:V27), 2), BIN2HEX(_xlfn.CONCAT(W27:AD27), 2) ) -> 0000008
A28: CCH
A29: CCH1 | O29: 0 | P29: 0 | Y29: 0 | Z29: 1 | AA29: 1 | AB29: 1 | AC29: 1 | AD29: 1 | AH29: =_xlfn.CONCAT(BIN2HEX(_xlfn.CONCAT(C29:F29), 1), BIN2HEX(_xlfn.CONCAT(G29:N29), 2), BIN2HEX(_xlfn.CONCAT(O29:V29), 2), BIN2HEX(_xlfn.CONCAT(W29:AD29), 2) ) -> 000001F
A30: CCH2 | O30: 0 | P30: 1 | Y30: 0 | Z30: 0 | AA30: 1 | AB30: 0 | AC30: 0 | AD30: 0 | AH30: =_xlfn.CONCAT(BIN2HEX(_xlfn.CONCAT(C30:F30), 1), BIN2HEX(_xlfn.CONCAT(G30:N30), 2), BIN2HEX(_xlfn.CONCAT(O30:V30), 2), BIN2HEX(_xlfn.CONCAT(W30:AD30), 2) ) -> 0000108

Sheet output
A1: 0 | B1: =DEC2BIN(A1, 6) -> 000000 | C1: BR0 | D1: 0000008 | G1: old instruction that got overwritten
A2: 1 | B2: =DEC2BIN(A2, 6) -> 000001 | C2: INC1 | D2: =microcode!AH4 -> 0000008
A3: 2 | B3: =DEC2BIN(A3, 6) -> 000010 | C3: LD1 | D3: 8041412
A4: 3 | B4: =DEC2BIN(A4, 6) -> 000011 | C4: LDAR1 | D4: =microcode!AH19 -> 0000113 | E4: *
A5: 4 | B5: =DEC2BIN(A5, 6) -> 000100 | C5: JSR0/JSRR0 | D5: 0000014 | F5: 0000014 | G5: JSR/JSRR
A6: 5 | B6: =DEC2BIN(A6, 6) -> 000101 | C6: CCH1 | D6: =microcode!AH29 -> 000001F | E6: * | F6: =microcode!AH9 -> 0000008 | G6: SETCC1
A7: 6 | B7: =DEC2BIN(A7, 6) -> 000110 | C7: MULT81 | D7: =microcode!AH15 -> 0000116 | E7: * | F7: =microcode!AH15 -> 0000116 | G7: LDN1
A8: 7 | B8: =DEC2BIN(A8, 6) -> 000111 | C8: LDPC1 | D8: =microcode!AH7 -> 0000017 | E8: * | F8: 8046C17 | G8: STR1
A9: 8 | B9: =DEC2BIN(A9, 6) -> 001000 | C9: FETCH1 | D9: 8600018
A10: 9 | B10: =DEC2BIN(A10, 6) -> 001001 | C10: NOT1 | D10: 1884208
A11: 10 | B11: =DEC2BIN(A11, 6) -> 001010 | C11: STPCI1 | D11: =microcode!AH23 -> 000001A | E11: * | F11: 804141A | G11: LDI1
A12: 11 | B12: =DEC2BIN(A12, 6) -> 001011 | C12: STI1 | D12: 804141B
A13: 12 | B13: =DEC2BIN(A13, 6) -> 001100 | C13: LJSR1 | D13: =microcode!AH12 -> 0000008 | E13: *
A14: 13 | B14: =DEC2BIN(A14, 6) -> 001101 | C14: LDSR1 | D14: 8084011
A15: 14 | B15: =DEC2BIN(A15, 6) -> 001110 | C15: LEA1 | D15: 1041408
A16: 15 | B16: =DEC2BIN(A16, 6) -> 001111 | C16: HALT | D16: 000000F
A17: 16 | B17: =DEC2BIN(A17, 6) -> 010000 | C17: BR1 | D17: 0411008
A18: 17 | B18: =DEC2BIN(A18, 6) -> 010001 | C18: LDSR2 | D18: 4000095
A19: 18 | B19: =DEC2BIN(A19, 6) -> 010010 | C19: LD2 | D19: 40000A2
A20: 19 | B20: =DEC2BIN(A20, 6) -> 010011 | C20: LDAR2 | D20: =microcode!AH20 -> 0000023 | E20: *
A21: 20 | B21: =DEC2BIN(A21, 6) -> 010100 | C21: JSR1 | D21: 1619808 | F21: 1619808 | G21: JSR1
A22: 21 | B22: =DEC2BIN(A22, 6) -> 010101 | C22: LDSR3 | D22: 1900008
A23: 22 | B23: =DEC2BIN(A23, 6) -> 010110 | C23: MULT82 | D23: =microcode!AH16 -> 0000126 | E23: *
A24: 23 | B24: =DEC2BIN(A24, 6) -> 010111 | C24: LDPC2 | D24: =microcode!AH8 -> 0000027 | E24: * | F24: 4080327 | G24: STR2
A25: 24 | B25: =DEC2BIN(A25, 6) -> 011000 | C25: FETCH2 | D25: 40000A8
A26: 25 | B26: =DEC2BIN(A26, 6) -> 011001 | C26: UNUSED**** | D26: 0
A27: 26 | B27: =DEC2BIN(A27, 6) -> 011010 | C27: STPCI2 | D27: =microcode!AH24 -> 000002A | E27: * | F27: 40000AA | G27: LDI2
A28: 27 | B28: =DEC2BIN(A28, 6) -> 011011 | C28: STI2 | D28: 40000AB
A29: 28 | B29: =DEC2BIN(A29, 6) -> 011100 | C29: UNUSED**** | D29: 0
A30: 29 | B30: =DEC2BIN(A30, 6) -> 011101 | C30: STPCI5 | D30: =microcode!AH27 -> 0000008 | E30: * | F30: 1900008 | G30: LDI5
A31: 30 | B31: =DEC2BIN(A31, 6) -> 011110 | C31: UNUSED**** | D31: 0
A32: 31 | B32: =DEC2BIN(A32, 6) -> 011111 | C32: CCH2 | D32: =microcode!AH30 -> 0000108 | E32: *
A33: 32 | B33: =DEC2BIN(A33, 6) -> 100000 | C33: UNUSED**** | D33: 0
A34: 33 | B34: =DEC2BIN(A34, 6) -> 100001 | C34: UNUSED**** | D34: 0
A35: 34 | B35: =DEC2BIN(A35, 6) -> 100010 | C35: LD3 | D35: 1900008
A36: 35 | B36: =DEC2BIN(A36, 6) -> 100011 | C36: LDAR3 | D36: =microcode!AH21 -> 0000008 | E36: *
A37: 36 | B37: =DEC2BIN(A37, 6) -> 100100 | C37: JSRR1 | D37: 161E008
A38: 37 | B38: =DEC2BIN(A38, 6) -> 100101 | C38: UNUSED**** | D38: 0
A39: 38 | B39: =DEC2BIN(A39, 6) -> 100110 | C39: MULT83 | D39: =microcode!AH17 -> 0000108 | E39: *
A40: 39 | B40: =DEC2BIN(A40, 6) -> 100111 | C40: LDPC3 | D40: =microcode!AH9 -> 0000008 | E40: * | F40: 00000C8 | G40: STR3
...
